<?xml version="1.0" encoding="utf-8"?>
<!-- This URDF was automatically created by SolidWorks to URDF Exporter! Originally created by Stephen Brawner (brawner@gmail.com) 
     Commit Version: 1.6.0-4-g7f85cfe  Build Version: 1.6.7995.38578
     For more information, please see http://wiki.ros.org/sw_urdf_exporter -->
<robot
  name="mobile_base">
  <link
    name="base_link">
    <inertial>
      <origin
        xyz="-0.000116077702547958 -0.0350031160113934 0.298943810669157"
        rpy="0 0 0" />
      <mass
        value="56"/>
      <inertia
        ixx="5.31"
        ixy="0.0"
        ixz="0.0"
        iyy="5.258"
        iyz="0.0"
        izz="5.310" />
    </inertial>
    <visual>
      <origin
        xyz="0 0 0"
        rpy="0 0 0" />
      <geometry>
        <mesh
          filename="package://mobile_base/meshes/base_link.STL" />
      </geometry>
      <material
        name="">
        <color
          rgba="0.615686274509804 0.811764705882353 0.925490196078431 1" />
      </material>
    </visual>
    <collision>
      <origin
        xyz="0 0 0"
        rpy="0 0 0" />
      <geometry>
        <mesh
          filename="package://mobile_base/meshes/base_link.STL" />
      </geometry>
    </collision>
  </link>
  <link
    name="f_l_prismatic">
    <inertial>
      <origin
        xyz="-1.66533453693773E-16 2.22044604925031E-16 -0.00277737910243356"
        rpy="0 0 0" />
      <mass
        value="0.63" />
      <inertia
        ixx="0.0"
        ixy="0.0"
        ixz="0.0"
        iyy="0.0"
        iyz="0.0"
        izz="0.0" />
    </inertial>
      <visual>
      <origin
        xyz="0 0 0"
        rpy="0 0 0" />
      <geometry>
        <mesh
          filename="package://mobile_base/meshes/f_l_prismatic.STL" />
      </geometry>
      <material
        name="">
        <color
          rgba="0.615686274509804 0.811764705882353 0.929411764705882 1" />
      </material>
    </visual>
    <collision>
      <origin
        xyz="0 0 0"
        rpy="0 0 0" />
      <geometry>
        <mesh
          filename="package://mobile_base/meshes/f_l_prismatic.STL" />
      </geometry>
    </collision>
  </link>
  <joint
    name="f_l_prismatic_joint"
    type="fixed">
    <origin
      xyz="0.2998 -0.33482 0.24287"
      rpy="0.0026114 0.002229 0" /> 
    <parent
      link="base_link" />
    <child
      link="f_l_prismatic" />
    <axis xyz="0 0 1" />
      <limit
      lower="0.01"
      upper="0.05"
      effort="1000"
      velocity="0" />
    <dynamics 
    damping="1"
    friction="0"
    spring_stiffness="0" 
    spring_referance="0" />
  </joint>
  <link
    name="f_l_rotate">
    <inertial>
      <origin
        xyz="-0.000108967571125163 -0.0488863047415668 -0.000127660035035393"
        rpy="0 0 0" />
      <mass
        value="0.35" />
      <inertia
        ixx="0.01"
        ixy="0.0"
        ixz="0.0"
        iyy="0.01"
        iyz="0.0"
        izz="0.0" />
    </inertial>
    <visual>
      <origin
        xyz="0 0 0"
        rpy="0 0 0" />
      <geometry>
        <mesh
          filename="package://mobile_base/meshes/f_1_rotate.STL" />
      </geometry>
      <material
        name="">
        <color
          rgba="0.615686274509804 0.811764705882353 0.929411764705882 1" />
      </material>
    </visual>
    <collision>
      <origin
        xyz="0 0 0"
        rpy="0 0 0" />
      <geometry>
        <mesh
          filename="package://mobile_base/meshes/f_1_rotate.STL" />
      </geometry>
    </collision>
  </link>
  <joint
    name="f_l_rotate_joint"
    type="revolute">
    <origin
      xyz="0 0 -0.0527773791024335"
      rpy="1.56818496671092 -0.00222898866464819 0" />
    <parent
      link="f_l_prismatic" />
    <child
      link="f_l_rotate" />
    <axis
      xyz="0.00222898681890077 0.999994106215458 0.00261135062896505" />
    <limit
      lower="-1.5708"
      upper="1.5708"
      effort="100"
      velocity="100" />
  </joint>
  <link
    name="f_l_ew">
    <inertial>
      <origin
        xyz="0 0 0"
        rpy="0 0 0" />
      <mass
        value="1.89" />
      <inertia
        ixx="018"
        ixy="0.01"
        ixz="0.17"
        iyy="0.34"
        iyz="0.01"
        izz="0.18" />
    </inertial>
    <visual>
      <origin
        xyz="0 0 0"
        rpy="0 0 0" />
      <geometry>
        <mesh
          filename="package://mobile_base/meshes/f_l_ew.STL" />
      </geometry>
      <material
        name="">
        <color
          rgba="0.615686274509804 0.811764705882353 0.929411764705882 1" />
      </material>
    </visual>
    <collision>
      <origin
        xyz="0 0 0"
        rpy="0 0 0" />
      <geometry>
        <mesh
          filename="package://mobile_base/meshes/f_l_ew.STL" />
      </geometry>
    </collision>
  </link>
  <joint
    name="f_l_ew_joint"
    type="continuous">
    <origin
      xyz="-0.000222898681890127 -0.0999994106215459 -0.000261135062896545"
      rpy="3.13936402790797 -1.57065442321589 0" />
    <parent
      link="f_l_rotate" />
    <child
      link="f_l_ew" />
    <axis
      xyz="0 0 1" />
    <limit
      effort="1000"
      velocity="100000" />
  </joint>
  <link
    name="f_r_prismatic">
    <inertial>
      <origin
        xyz="-1.11022302462516E-16 1.11022302462516E-16 -0.0027773791024335"
        rpy="0 0 0" />  
      <mass
        value="0.63" />
      <inertia
        ixx="0.0"
        ixy="0.0"
        ixz="0.0"
        iyy="0.0"
        iyz="0.0"
        izz="0.0" />
    </inertial>
     <visual>
      <origin
        xyz="0 0 0"
        rpy="0 0 0" />
      <geometry>
        <mesh
          filename="package://mobile_base/meshes/f_r_prismatic.STL" />
      </geometry>
      <material
        name="">
        <color
          rgba="0.615686274509804 0.811764705882353 0.929411764705882 1" />
      </material>
    </visual>
    <collision>
      <origin
        xyz="0 0 0"
        rpy="0 0 0" />
      <geometry>
        <mesh
          filename="package://mobile_base/meshes/f_r_prismatic.STL" />
      </geometry>
    </collision>
  </link>
  <joint
    name="f_r_prismatic_joint"
    type="fixed">
    <origin
      xyz="-0.3002 -0.3349 0.24421"
      rpy="0.0026114 0.002229 0" />
    <parent
      link="base_link" />
    <child
      link="f_r_prismatic" />
    <axis
      initial_position = "500"
      xyz="0 0 1" />
    <limit
      lower="0.01"
       upper="0.05"
      effort="1000"
      velocity="0" />
    <dynamics 
    damping="1"  
    friction="0"
    spring_stiffness="0" 
    spring_referance="0"/>
  </joint>
  <link
    name="f_r_rotate">
    <inertial>
      <origin
        xyz="-0.000108967571125163 -0.0488863047415668 -0.000127660035035393"
        rpy="0 0 0" />
      <mass
        value="0.35" />
      <inertia
        ixx="01"
        ixy="0.0"
        ixz="0.0"
        iyy="1"
        iyz="0.0"
        izz="0.0" />
    </inertial>
    <visual>
      <origin
        xyz="0 0 0"
        rpy="0 0 0" />
      <geometry>
        <mesh
          filename="package://mobile_base/meshes/f_r_rotate.STL" />
      </geometry>
      <material
        name="">
        <color
          rgba="0.615686274509804 0.811764705882353 0.929411764705882 1" />
      </material>
    </visual>
    <collision>
      <origin
        xyz="0 0 0"
        rpy="0 0 0" />
      <geometry>
        <mesh
          filename="package://mobile_base/meshes/f_r_rotate.STL" />
      </geometry>
    </collision>
  </link>
  <joint
    name="f_r_rotate_joint"
    type="revolute">
    <origin
      xyz="0 0 -0.0527773791024335"
      rpy="1.56818496671092 -0.00222898866464819 0" />
    <parent
      link="f_r_prismatic" />
    <child
      link="f_r_rotate" />
    <axis
      xyz="0.00222898681890077 0.999994106215458 0.00261135062896505" />
    <limit
      lower="-1.5708"
      upper="1.5708"
      effort="100"
      velocity="100" />
  </joint>
   <link
    name="f_r_ew">
    <inertial>
      <origin
        xyz="5.55111512312578E-17 0 0"
        rpy="0 0 0" />
      <mass
        value="1.89" />
      <inertia
        ixx="018"
        ixy="0.01"
        ixz="0.17"
        iyy="0.34"
        iyz="0.01"
        izz="0.18" />
    </inertial>
    <visual>
      <origin
        xyz="0 0 0"
        rpy="0 0 0" />
      <geometry>
        <mesh
          filename="package://mobile_base/meshes/f_r_ew.STL" />
      </geometry>
      <material
        name="">
        <color
          rgba="0.615686274509804 0.811764705882353 0.929411764705882 1" />
      </material>
    </visual>
    <collision>
      <origin
        xyz="0 0 0"
        rpy="0 0 0" />
      <geometry>
        <mesh
          filename="package://mobile_base/meshes/f_r_ew.STL" />
      </geometry>
     </collision>
   </link>
  <joint
    name="f_r_ew_joint"
    type="continuous">
    <origin
      xyz="-0.000222898681890127 -0.0999994106215459 -0.000261135062896545"
      rpy="3.13936402790797 -1.57065442321589 0" />
    <parent
      link="f_r_rotate" />
    <child
      link="f_r_ew" />
    <axis
      xyz="0 0 1" />
    <limit
      effort="1000"
      velocity="100000" />
  </joint>
  <link
    name="r_r_prismatic">
    <inertial>
      <origin
        xyz="-5.55111512312578E-17 1.11022302462516E-16 -0.00277737910243359"
        rpy="0 0 0" />
      <mass
        value="0.63" />
      <inertia
        ixx="0.0"
        ixy="0.0"
        ixz="0.0"
        iyy="0.0"
        iyz="0.0"
        izz="0.0" />
    </inertial>

    <visual>
      <origin
        xyz="0 0 0"
        rpy="0 0 0" />
      <geometry>
        <mesh
          filename="package://mobile_base/meshes/r_r_prismatic.STL" />
      </geometry>
      <material
        name="">
        <color
          rgba="0.615686274509804 0.811764705882353 0.929411764705882 1" />
      </material>
    </visual>
    <collision>
      <origin
        xyz="0 0 0"
        rpy="0 0 0" />
      <geometry>
        <mesh
          filename="package://mobile_base/meshes/r_r_prismatic.STL" />
      </geometry>
    </collision>
  </link>
  <joint
    name="r_r_prismatic_joint"
    type="fixed">
    <origin
      xyz="-0.30028 0.2651 0.24578"
      rpy="0.0026114 0.002229 0" /> 
    <parent
      link="base_link" />
    <child
      link="r_r_prismatic" />
    <axis
      
      xyz="0 0 1" />
    <limit
      lower="0.01"
       upper="0.05"
      effort="1000"
      velocity="0" />
    <dynamics 
    damping="1"
    friction="0"
    spring_stiffness="0" 
    spring_referance="0" />
  </joint>
  <link
    name="r_r_rotate">
    <inertial>
      <origin
        xyz="-0.000108967571125107 -0.0488863047415668 -0.000127660035035393"
        rpy="0 0 0" />
      <mass
        value="0.35" />
      <inertia
        ixx="0.01"
        ixy="0.0"
        ixz="0.0"
        iyy="0.01"
        iyz="0.0"
        izz="0.0" />
    </inertial>
    <visual>
      <origin
        xyz="0 0 0"
        rpy="0 0 0" />
      <geometry>
        <mesh
          filename="package://mobile_base/meshes/r_r_rotate.STL" />
      </geometry>
      <material
        name="">
        <color
          rgba="0.615686274509804 0.811764705882353 0.929411764705882 1" />
      </material>
    </visual>
    <collision>
      <origin
        xyz="0 0 0"
        rpy="0 0 0" />
      <geometry>
        <mesh
          filename="package://mobile_base/meshes/r_r_rotate.STL" />
      </geometry>
    </collision>
  </link>
  <joint
    name="r_r_rotate_joint"
    type="revolute">
    <origin
      xyz="0 0 -0.0527773791024335"
      rpy="1.56818496671092 -0.00222898866464819 0" />
    <parent
      link="r_r_prismatic" />
    <child
      link="r_r_rotate" />
    <axis
      xyz="0.00222898681890077 0.999994106215458 0.00261135062896505" />
    <limit
      lower="-1.5708" 
      upper="1.5708"
      effort="100"
      velocity="100" />
  </joint>
   <link
    name="r_r_ew">
    <inertial>
      <origin
        xyz="0 0 0"
        rpy="0 0 0" />
      <mass
        value="1.89" />
      <inertia
        ixx="018"
        ixy="0.01"
        ixz="0.17"
        iyy="0.34"
        iyz="0.01"
        izz="0.18" />
    </inertial>
    <visual>
      <origin
        xyz="0 0 0"
        rpy="0 0 0" />
      <geometry>
        <mesh
          filename="package://mobile_base/meshes/r_r_ew.STL" />
      </geometry>
      <material
        name="">
        <color
          rgba="0.615686274509804 0.811764705882353 0.929411764705882 1" />
      </material>
    </visual>
    <collision>
      <origin
        xyz="0 0 0"
        rpy="0 0 0" />
      <geometry>
        <mesh
          filename="package://mobile_base/meshes/r_r_ew.STL" />
      </geometry>
    </collision>
  </link>
  <joint
    name="r_r_ew_joint"
    type="continuous">
    <origin
      xyz="-0.000222898681890127 -0.0999994106215459 -0.000261135062896489"
      rpy="3.13936402790797 -1.57065442321589 0" />
    <parent
      link="r_r_rotate" />
    <child
      link="r_r_ew" />
    <axis
      xyz="0 0 1" />
   <limit
      effort="1000"
      velocity="100000" />
  </joint>
  <link
    name="r_l_prismatic">
    <inertial>
      <origin
        xyz="0 1.66533453693773E-16 -0.0027773791024335"
        rpy="0 0 0" />
      <mass
        value="0.63" />
      <inertia
        ixx="0.0"
        ixy="0.0"
        ixz="0.0"
        iyy="0.0"
        iyz="0.0"
        izz="0.0" />
    </inertial>
 
    <visual>
      <origin
        xyz="0 0 0"
        rpy="0 0 0" />
      <geometry>
        <mesh
          filename="package://mobile_base/meshes/r_l_prismatic.STL" />
      </geometry>
      <material
        name="">
        <color
          rgba="0.615686274509804 0.811764705882353 0.929411764705882 1" />
      </material>
    </visual>
    <collision>
      <origin
        xyz="0 0 0"
        rpy="0 0 0" />
      <geometry>
        <mesh
          filename="package://mobile_base/meshes/r_l_prismatic.STL" />
      </geometry>
    </collision>
  </link>

  <joint
    name="r_l_prismatic_joint"
    type="fixed">
    <origin
      xyz="0.299720607952755 0.265181054293093 0.24444162435061"
      rpy="0.00261136657109324 0.00222898106467852 0" /> 
    <parent
      link="base_link" />
    <child
      link="r_l_prismatic" />
    <axis
      xyz="0 0 1" />
    <limit
      lower="0.01"
      upper="0.05"
      effort="1000"
      velocity="0" />
    <dynamics 
      damping="1"
      friction="0"
      spring_stiffness="0" 
      spring_referance="0"
      />
  </joint>
   <link
    name="r_l_rotate">
    <inertial>
      <origin
        xyz="-0.000108967571125052 -0.0488863047415668 -0.000127660035035393"
        rpy="0 0 0" />
      <mass
        value="0.35" />
      <inertia
        ixx="0.01"
        ixy="0.0"
        ixz="0.0"
        iyy="0.01"
        iyz="0.0"
        izz="0.0" />
    </inertial>
    <visual>
      <origin
        xyz="0 0 0"
        rpy="0 0 0" />
      <geometry>
        <mesh
          filename="package://mobile_base/meshes/r_l_rotate.STL" />
      </geometry>
      <material
        name="">
        <color
          rgba="0.615686274509804 0.811764705882353 0.929411764705882 1" />
      </material>
    </visual>
    <collision>
      <origin
        xyz="0 0 0"
        rpy="0 0 0" />
      <geometry>
        <mesh
          filename="package://mobile_base/meshes/r_l_rotate.STL" />
      </geometry>
    </collision>
  </link>
  <joint
    name="r_l_rotate_joint"
    type="revolute">
    <origin
      xyz="0 0 -0.0527773791024335"
      rpy="1.56818496671092 -0.00222898866464819 0" />
    <parent
      link="r_l_prismatic" />
    <child
      link="r_l_rotate" />
    <axis
      xyz="0.00222898681890077 0.999994106215458 0.00261135062896505" />
    <limit
      lower="-1.5708"
      upper="1.5708"
      effort="100"
      velocity="100" />
  </joint>
  <link
    name="r_l_ew">
    <inertial>
      <origin
        xyz="0 1.38777878078145E-17 0"
        rpy="0 0 0" />
      <mass
        value="1.89" />
      <inertia
        ixx="018"
        ixy="0.01"
        ixz="0.17"
        iyy="0.34"
        iyz="0.01"
        izz="0.18" />
    </inertial>
    <visual>
      <origin
        xyz="0 0 0"
        rpy="0 0 0" />
      <geometry>
        <mesh
          filename="package://mobile_base/meshes/r_l_ew.STL" />
      </geometry>
      <material
        name="">
        <color
          rgba="0.615686274509804 0.811764705882353 0.929411764705882 1" />
      </material>
    </visual>
    <collision>
      <origin
        xyz="0 0 0"
        rpy="0 0 0" />
      <geometry>
        <mesh
          filename="package://mobile_base/meshes/r_l_ew.STL" />
      </geometry>
    </collision>
  </link>
 <joint
    name="r_l_ew_joint"
    type="continuous">
    <origin
      xyz="-0.000222898681890127 -0.0999994106215459 -0.000261135062896489"
      rpy="3.13936402790797 -1.57065442321589 0" />
      
    <parent
      link="r_l_rotate" />
    <child
      link="r_l_ew" />
    <axis
      xyz="0 0 1" />
    <limit
      effort="1000"
      velocity="100000" />
  </joint>


  <transmission name="f_l_ew_trans">
    <type>transmission_interface/SimpleTransmission</type>
    <joint name="f_l_ew_joint">
      <hardwareInterface>hardware_interface/VelocityJointInterface</hardwareInterface>
    </joint>
    <actuator name="f_l_ew_motor">
      <hardwareInterface>hardware_interface/VelocityJointInterface</hardwareInterface>
      <mechanicalReduction>1</mechanicalReduction>
    </actuator>
  </transmission>
  
  <transmission name="f_r_ew_trans">
    <type>transmission_interface/SimpleTransmission</type>
    <joint name="f_r_ew_joint">
      <hardwareInterface>hardware_interface/VelocityJointInterface</hardwareInterface>
    </joint>
    <actuator name="f_r_ew_motor">
      <hardwareInterface>hardware_interface/VelocityJointInterface</hardwareInterface>
      <mechanicalReduction>1</mechanicalReduction>
    </actuator>
  </transmission>
  
  <transmission name="r_l_ew_trans">
    <type>transmission_interface/SimpleTransmission</type>
    <joint name="r_l_ew_joint">
      <hardwareInterface>hardware_interface/VelocityJointInterface</hardwareInterface>
    </joint>
    <actuator name="r_l_ew_motor">
      <hardwareInterface>hardware_interface/VelocityJointInterface</hardwareInterface>
      <mechanicalReduction>1</mechanicalReduction>
    </actuator>
  </transmission>
  
  <transmission name="r_r_ew_trans">
    <type>transmission_interface/SimpleTransmission</type>
    <joint name="r_r_ew_joint">
      <hardwareInterface>hardware_interface/VelocityJointInterface</hardwareInterface>
    </joint>
    <actuator name="r_r_ew_motor">
      <hardwareInterface>hardware_interface/VelocityJointInterface</hardwareInterface>
      <mechanicalReduction>1</mechanicalReduction>
    </actuator>
  </transmission>

  <!--  -->
  <transmission name="f_l_rotate_trans">
    <type>transmission_interface/SimpleTransmission</type>
    <joint name="f_l_rotate_joint">
      <hardwareInterface>hardware_interface/PositionJointInterface</hardwareInterface>
    </joint>
    <actuator name="f_l_rotate_motor">
      <hardwareInterface>hardware_interface/PositionJointInterface</hardwareInterface>
      <mechanicalReduction>1</mechanicalReduction>
    </actuator>
  </transmission>
  
  <transmission name="f_r_rotate_trans">
    <type>transmission_interface/SimpleTransmission</type>
    <joint name="f_r_rotate_joint">
      <hardwareInterface>hardware_interface/PositionJointInterface</hardwareInterface>
    </joint>
    <actuator name="f_r_rotate_motor">
      <hardwareInterface>hardware_interface/PositionJointInterface</hardwareInterface>
      <mechanicalReduction>1</mechanicalReduction>
    </actuator>
  </transmission>
  
  <transmission name="r_l_rotate_trans">
    <type>transmission_interface/SimpleTransmission</type>
    <joint name="r_l_rotate_joint">
      <hardwareInterface>hardware_interface/PositionJointInterface</hardwareInterface>
    </joint>
    <actuator name="r_l_rotate_motor">
      <hardwareInterface>hardware_interface/PositionJointInterface</hardwareInterface>
      <mechanicalReduction>1</mechanicalReduction>
    </actuator>
  </transmission>
  
  <transmission name="r_r_rotate_trans">
    <type>transmission_interface/SimpleTransmission</type>
    <joint name="r_r_rotate_joint">
      <hardwareInterface>hardware_interface/PositionJointInterface</hardwareInterface>
    </joint>
    <actuator name="r_r_rotate_motor">
      <hardwareInterface>hardware_interface/PositionJointInterface</hardwareInterface>
      <mechanicalReduction>1</mechanicalReduction>
    </actuator>
  </transmission>




  <gazebo>
    <plugin name="gazebo_ros_control" filename="libgazebo_ros_control.so">
     <robotNamespace>/mobile_base</robotNamespace>
     <robotSimType>gazebo_ros_control/DefaultRobotHWSim</robotSimType>
    </plugin>
  </gazebo> 
  
 
</robot>